Workbook

Sheet СР отгрузка 1 в 26
P2: УТВЕРЖДАЮ:
P3: Руководитель предприятия
P4: Алтухова Е.А. __________________
P6: "____" _________________ 2026 г.
B7: Акт № 1
B8: о приёмке товарно-материальных ценностей
B9: от 14.09.2026 г.
B11: Инвойс CTI2026000000504 от 16.07.2026
B12: Упаковочный лист (количество мест, вес, объем) 0 коробок, 19 паллет, 54.13 м³, вес брутто - 7506 кг, вес нетто - 7296 кг.
B13: Состояние упаковки (вскрытая, потертая, помятая, рваная и т.д.) – удовлетворительное.
B14: Дата забора груза от отправителя: | F14: 46220 | G14: г.
B15: Дата выезда продукции (товара) из г. Стамбул: | G15: 46231 | H15: г.
B16: Дата ТО (таможенного оформления): | F16: 46258 | G16: г.
B17: Дата поступления продукции (товара) на склад: | G17: 46272 | H17: г.
B19: Поступление: | D19: Cetinkaya Pano инвойс | F19: 27161.47 | G19: EUR
B21: Мы, нижеподписавшиеся, составили настоящий акт о приёмке товарно-материальных ценностей:
B23: Этапы сверки
B25: № п/п | C25: Этапы сверки | E25: Номенклатура | G25: Кол-во, шт | J25: Цена за ед., евро (EXW) | K25: Итого, евро (EXW) | L25: Заказ поставщику | P25: Примечание | T25: Ответственный
G26: в инвойсе | H26: факт | I26: ∆
B27: 1 | C27: Расхождения между упаковочным листом и инвойсом | E27: Нет | T27: Макеева И.В.
B28: 2 | C28: Расхождения между упаковочным листом и пришедшим товаром | E28: CP1043Y | G28: 10 | H28: 12 | I28: =H28-G28 | J28: 7.46 | K28: =J28*I28 | P28: Излишек | T28: Макеева И.В. Никулин А.И.
E29: CP10912 | G29: 12 | H29: 14 | I29: =H29-G29 | J29: 5.97 | K29: =J29*I29 | P29: Излишек
E30: CP6901 | G30: 80 | H30: 77 | I30: =H30-G30 | J30: 0.65 | K30: =J30*I30 | P30: +30% от стоимости затраты НДС, пошлины
E31: S21 C12K 01 | G31: 5 | H31: 6 | I31: =H31-G31 | J31: 12.63 | K31: =J31*I31 | P31: Излишек
E32: S21 C12K 02 | G32: 5 | H32: 4 | I32: =H32-G32 | J32: 15.79 | K32: =J32*I32 | P32: +30% от стоимости затраты НДС, пошлины
E33: V03 220 001 | G33: 5 | H33: 2 | I33: =H33-G33 | J33: 59 | K33: =J33*I33 | P33: +30% от стоимости затраты НДС, пошлины
E34: V05 060 001 | G34: 10 | H34: 17 | I34: =H34-G34 | J34: 2.25 | K34: =J34*I34 | P34: Излишек
E35: V05 060 002 | G35: 10 | H35: 3 | I35: =H35-G35 | J35: 2.25 | K35: =J35*I35 | P35: +30% от стоимости затраты НДС, пошлины
E40: Итого: | K40: =SUM(K28:K39)
B41: 3 | C41: Расхождения по ценам инвойса и входным в программе 1С | E41: Нет | P41: Сверено с документом 1С «Приобретение товаров № КА-358 от 24 августа 2026 г.». Разная ед. изм. без расхождения по сумме: 17 поз. (CWD) — цена в 1С ×2.0, кол-во соответственно меньше | T41: Макеева И.В.
B42: 4 | C42: Расхождения между инвойсом и заказом поставщику (справочно) | E42: Нет | T42: Макеева И.В.
E65: Итого: | K65: =SUM(K42:K64)
B66: 5 | C66: Расхождение по сумме поступлений и инвойса | E66: 1. Стоимость товара согласно таможенным документам (сумма в инвойсе) составила: | K66: =F19 | L66: EUR | T66: Макеева И.В.
E67: 2. Стоимость фактического поступившего товара с оприходованием и недостачей составила: | K67: =K66+K40 | L67: EUR
E68: 3. Разница в стоимости между фактическим поступлением и инвойсом составляет: | K68: =K67-K66 | L68: =IF(K68<0,"евро в пользу Ритет","евро в пользу Эмас")
B69: 6 | C69: Затраты на доставку и ТО
C70: Инвойс | F70: Стоимость доставки до границы ("КВТ Сервис") | H70: Стоимость доставки РФ + Брокер ("КВТ Сервис") | J70: Погрузо-разгрузочные работы ("КВТ Сервис") | L70: Таможенный сбор | N70: Пошлина | P70: НДС | R70: Оплатили по факту и % от инвойса
F71: доллар | H71: евро | J71: евро | L71: евро | N71: евро | P71: евро | R71: евро | S71: =G71+I71+K71+M71+O71+Q71
C72: поставщик | D72: евро | E72: % | F72: рубли | G72: 169988.26 | H72: рубли | I72: 347558.85 | J72: рубли | K72: 66500 | L72: рубли | M72: 73860 | N72: рубли | O72: 176989.31 | P72: рубли | Q72: 656100.41 | R72: рубли | S72: =G72+I72+K72+M72+O72+Q72
C73: Cetinkaya Pano | D73: =F19 | F73: % | G73: =(G71*U79+G72)*100/(D73*U79) | H73: % | I73: =(I71*U79+I72)*100/(D73*U79) | J73: % | K73: =(K71*U79+K72)*100/(D73*U79) | L73: % | M73: =(M71*U79+M72)*100/(D73*U79) | N73: % | O73: =(O71*U79+O72)*100/(D73*U79) | P73: % | Q73: =(Q71*U79+Q72)*100/(D73*U79) | R73: % | S73: =(S71*U79+S72)*100/(D73*U79)
...

Sheet Затраты на доставку и ТО
A1: Курс валют на:
A2: ='СР отгрузка 1 в 26'!F16
A3: Валюта | B3: ₱ рубль
A4: 1$ доллар | B4: ='СР отгрузка 1 в 26'!U78
A5: 1евро | B5: ='СР отгрузка 1 в 26'!U79
A6: К =1€ / 1$ | B6: =B5/B4
A8: Затраты на доставку и ТО
A9: Инвойс | D9: Стоимость доставки до границы ("КВТ Сервис") | F9: Стоимость доставки РФ + Брокер ("КВТ Сервис") | H9: Погрузо-разгрузочные работы ("КВТ Сервис") | J9: Таможенный сбор | L9: Пошлина | N9: НДС | P9: Оплатили по факту и % от инвойса
D10: доллар | E10: ='СР отгрузка 1 в 26'!G71 | F10: евро | H10: евро | J10: евро | L10: евро | N10: евро | P10: евро | Q10: =E10+G10+I10+K10+M10+O10
A11: поставщик | B11: евро | C11: % | D11: рубли | E11: ='СР отгрузка 1 в 26'!G72 | F11: рубли | G11: ='СР отгрузка 1 в 26'!I72 | H11: рубли | I11: ='СР отгрузка 1 в 26'!K72 | J11: рубли | K11: ='СР отгрузка 1 в 26'!M72 | L11: рубли | M11: ='СР отгрузка 1 в 26'!O72 | N11: рубли | O11: ='СР отгрузка 1 в 26'!Q72 | P11: рубли | Q11: =E11+G11+I11+K11+M11+O11
A12: EMAS | B12: ='СР отгрузка 1 в 26'!F19 | D12: % | E12: =(E10*B5+E11)*100/(B12*B5) | F12: % | G12: =(G10*B5+G11)*100/(B12*B5) | H12: % | I12: =(I10*B5+I11)*100/(B12*B5) | J12: % | K12: =(K10*B5+K11)*100/(B12*B5) | L12: % | M12: =(M10*B5+M11)*100/(B12*B5) | N12: % | O12: =(O10*B5+O11)*100/(B12*B5) | P12: % | Q12: =(Q10*B5+Q11)*100/(B12*B5)
J14: Продакт-менеджер: | L14: ='СР отгрузка 1 в 26'!F76 | P14: / Макеева И.В.
J17: Главный бухгалтер: | L17: " " апреля 2026 г. | P17: / Мосеенков А.С.
