Workbook
Name _FilterDatabase: '[1]Отгрузка ЭМАС 3'!$B$25:$U$73
Name Print_Area: '[1]Отгрузка ЭМАС 3'!$A$1:$U$84

Sheet EMAS отгрузка 1 в 26
P2: УТВЕРЖДАЮ:
P3: Руководитель предприятия
P4: Алтухова Е.А. __________________
P6: "____" _________________ 2026 г.
B7: Акт № 1
B8: о приёмке товарно-материальных ценностей
B9: от 27.01.2026 г.
B11: Инвойс EMA2025000005907, EMA2025000005908 от 09.12.2025
B12: Упаковочный лист (количество мест, вес, объем) 250 коробок, 10 паллет, 25,8 м³, вес брутто - 5 059 кг, вес нетто - 4 766,32 кг.
B13: Состояние упаковки (вскрытая, потертая, помятая, рваная и т.д.) – удовлетворительное.
B14: Дата забора груза от отправителя: | F14: 46001.875 | G14: г.
B15: Дата выезда продукции (товара) из г. Стамбул: | G15: 46002.875 | H15: г.
B16: Дата ТО (таможенного оформления): | F16: 46008.875 | G16: г.
B17: Дата поступления продукции (товара) на склад: | G17: 46033.875 | H17: г.
B19: Поступление: | D19: EMAS инвойс | F19: 110633.45 | G19: EUR
B21: Мы, нижеподписавшиеся, составили настоящий акт о приёмке товарно-материальных ценностей:
B23: Этапы сверки
B25: № п/п | C25: Этапы сверки | E25: Номенклатура | G25: Кол-во, шт | J25: Цена за ед., евро (EXW) | K25: Итого, евро (EXW) | L25: Заказ поставщику | P25: Примечание | T25: Ответственный
G26: в инвойсе | H26: факт | I26: ∆
B27: 1 | C27: Расхождения между упаковочным листом и инвойсом | E27: Нет | T27: Макеева И.В.
B28: 2 | C28: Расхождения между упаковочным листом и пришедшим товаром | E28: CSMKOLTAK | G28: 10 | H28: 20 | I28: =H28-G28 -> 10 | J28: 1.426 | K28: =J28*I28 -> 14.26 | P28: Излишек | T28: Макеева И.В. Никулин А.И.
E29: CSMKOLTAK3 | G29: 10 | H29: 0 | I29: =H29-G29 -> -10 | J29: 1.795 | K29: =J29*I29 -> -17.95 | P29: +30% от стоимости затраты НДС, пошлины
E40: Итого: | K40: =SUM(K28:K39) -> -3.69
B41: 3 | C41: Расхождения по ценам инвойса и входным в программе 1С | E41: Есть: 50 позиций — L52K13MUM331: инвойс 6.58, 1С 6.58; PA1155: инвойс 3.67, 1С 3.67; PA8851-10B: инвойс 22.70, 1С 22.70; CP100DS: инвойс 1.60, 1С 1.60; IKM5K: инвойс 2.67, 1С 2.67; IK53L024XM03: инвойс 20.99, 1С 20.99 | P41: Сверено с документом 1С «Приобретение товаров № КА-450 от 18 декабря 2025 г.». ВНИМАНИЕ: в 1С колонка «Сумма» ≠ кол-во×цена по 53 поз. (L52K13MUM331, PA1155, PA8851-10B, CP100DS, IKM5K) — итого +2,23 EUR; итог документа завышен | T41: Макеева И.В.
B42: 4 | C42: Расхождения между инвойсом и заказом поставщику (справочно) | E42: Нет | T42: Макеева И.В.
E65: Итого: | K65: =SUM(K42:K64) -> 0
B66: 5 | C66: Расхождение по сумме поступлений и инвойса | E66: 1. Стоимость товара согласно таможенным документам (сумма в инвойсе) составила: | K66: =F19 -> 110633.45 | L66: EUR | T66: Макеева И.В.
E67: 2. Стоимость фактического поступившего товара с оприходованием и недостачей составила: | K67: =K66+K40 -> 110629.76 | L67: EUR
E68: 3. Разница в стоимости между фактическим поступлением и инвойсом составляет: | K68: =K67-K66 -> -3.69 | L68: =IF(K68<0,"евро в пользу Ритет","евро в пользу Эмас") -> евро в пользу Ритет
B69: 6 | C69: Затраты на доставку и ТО
C70: Инвойс | F70: Стоимость доставки до границы ("КВТ Сервис") | H70: Стоимость доставки РФ + Брокер ("КВТ Сервис") | J70: Погрузо-разгрузочные работы ("КВТ Сервис") | L70: Таможенный сбор | N70: Пошлина | P70: НДС | R70: Оплатили по факту и % от инвойса
F71: доллар | H71: евро | J71: евро | L71: евро | N71: евро | P71: евро | R71: евро | S71: =G71+I71+K71+M71+O71+Q71 -> 0
C72: поставщик | D72: евро | E72: % | F72: рубли | G72: 136647.19 | H72: рубли | I72: 33800 | J72: рубли | K72: 200000 | L72: рубли | M72: 30000 | N72: рубли | O72: 107533.43 | P72: рубли | Q72: 2132607.2 | R72: рубли | S72: =G72+I72+K72+M72+O72+Q72 -> 2640587.8
C73: EMAS | D73: =F19 -> 110633.45 | F73: % | G73: =(G71*U79+G72)*100/(D73*U79) -> 1.3119101 | H73: % | I73: =(I71*U79+I72)*100/(D73*U79) -> 0.32450401 | J73: % | K73: =(K71*U79+K72)*100/(D73*U79) -> 1.9201421 | L73: % | M73: =(M71*U79+M72)*100/(D73*U79) -> 0.28802131 | N73: % | O73: =(O71*U79+O72)*100/(D73*U79) -> 1.0323973 | P73: % | Q73: =(Q71*U79+Q72)*100/(D73*U79) -> 20.474544 | R73: % | S73: =(S71*U79+S72)*100/(D73*U79) -> 25.351519
S75: Курс валют на:
E76: Начальник склада: | F76: "27" января 2026г. | K76: /А.И. Никулин | T76: =F16 -> 46008.875 | U76: г.
S77: валюта | U77: ₱ рубль
S78: 1$ доллар | U78: 80.3807
E79: Продакт-менеджер: | F79: "27" января 2026г. | K79: / И.В. Макеева | S79: 1евро | U79: 94.1478
S80: К =1€ / 1$ | U80: =U79/U78 -> 1.1712737
...

Sheet Затраты на доставку и ТО
A1: Курс валют на:
A2: ='EMAS отгрузка 1 в 26'!F16 -> 46008.875
A3: Валюта | B3: ₱ рубль
A4: 1$ доллар | B4: ='EMAS отгрузка 1 в 26'!U78 -> 80.3807
A5: 1евро | B5: ='EMAS отгрузка 1 в 26'!U79 -> 94.1478
A6: К =1€ / 1$ | B6: =B5/B4 -> 1.1712737
A8: Затраты на доставку и ТО
A9: Инвойс | D9: Стоимость доставки до границы ("КВТ Сервис") | F9: Стоимость доставки РФ + Брокер ("КВТ Сервис") | H9: Погрузо-разгрузочные работы ("КВТ Сервис") | J9: Таможенный сбор | L9: Пошлина | N9: НДС | P9: Оплатили по факту и % от инвойса
D10: доллар | E10: ='EMAS отгрузка 1 в 26'!G71 -> 0 | F10: евро | H10: евро | J10: евро | L10: евро | N10: евро | P10: евро | Q10: =E10+G10+I10+K10+M10+O10 -> 0
A11: поставщик | B11: евро | C11: % | D11: рубли | E11: ='EMAS отгрузка 1 в 26'!G72 -> 136647.19 | F11: рубли | G11: ='EMAS отгрузка 1 в 26'!I72 -> 33800 | H11: рубли | I11: ='EMAS отгрузка 1 в 26'!K72 -> 200000 | J11: рубли | K11: ='EMAS отгрузка 1 в 26'!M72 -> 30000 | L11: рубли | M11: ='EMAS отгрузка 1 в 26'!O72 -> 107533.43 | N11: рубли | O11: ='EMAS отгрузка 1 в 26'!Q72 -> 2132607.2 | P11: рубли | Q11: =E11+G11+I11+K11+M11+O11 -> 2640587.8
A12: EMAS | B12: ='EMAS отгрузка 1 в 26'!F19 -> 110633.45 | D12: % | E12: =(E10*B5+E11)*100/(B12*B5) -> 1.3119101 | F12: % | G12: =(G10*B5+G11)*100/(B12*B5) -> 0.32450401 | H12: % | I12: =(I10*B5+I11)*100/(B12*B5) -> 1.9201421 | J12: % | K12: =(K10*B5+K11)*100/(B12*B5) -> 0.28802131 | L12: % | M12: =(M10*B5+M11)*100/(B12*B5) -> 1.0323973 | N12: % | O12: =(O10*B5+O11)*100/(B12*B5) -> 20.474544 | P12: % | Q12: =(Q10*B5+Q11)*100/(B12*B5) -> 25.351519
J14: Продакт-менеджер: | L14: ='EMAS отгрузка 1 в 26'!F76 -> "27" января 2026г. | P14: / Макеева И.В.
J17: Главный бухгалтер: | L17: " " апреля 2026 г. | P17: / Мосеенков А.С.
